<?xml version="1.0" ?>
<robot name="zine_rover" xmlns:xacro="http://www.ros.org/wiki/xacro">

<xacro:include filename="$(find zine_rover_description)/urdf/materials.xacro" />
<!-- <xacro:include filename="$(find zine_rover_description)/urdf/zine_rover.trans" /> -->
<xacro:include filename="$(find zine_rover_description)/urdf/zine_rover.gazebo" />
<link name="base_link">
  <inertial>
    <origin xyz="-0.008464028434987501 -0.00012720246340532364 0.29059860690266914" rpy="0 0 0"/>
    <mass value="38.73454767745476"/>
    <inertia ixx="1.01308" iyy="0.912457" izz="1.613929" ixy="0.000567" iyz="-0.000288" ixz="-0.01019"/>
  </inertial>
  <visual>
    <origin xyz="0 0 0" rpy="0 0 0"/>
    <geometry>
      <mesh filename="file://$(find zine_rover_description)/meshes/base_link.stl" scale="0.001 0.001 0.001"/>
    </geometry>
    <material name="silver"/>
  </visual>
  <collision>
    <origin xyz="0 0 0" rpy="0 0 0"/>
    <geometry>
      <mesh filename="file://$(find zine_rover_description)/meshes/base_link.stl" scale="0.001 0.001 0.001"/>
    </geometry>
  </collision>
</link>

<link name="right_leg_link_1">
  <inertial>
    <origin xyz="-0.0013207563354463506 0.06659219509746495 -0.1092914309676741" rpy="0 0 0"/>
    <mass value="16.47124704533649"/>
    <inertia ixx="0.117611" iyy="0.774902" izz="0.677974" ixy="-0.000289" iyz="-0.008207" ixz="-0.000244"/>
  </inertial>
  <visual>
    <origin xyz="-0.025571 0.370084 -0.330926" rpy="0 0 0"/>
    <geometry>
      <mesh filename="file://$(find zine_rover_description)/meshes/right_leg_link_1.stl" scale="0.001 0.001 0.001"/>
    </geometry>
    <material name="silver"/>
  </visual>
  <collision>
    <origin xyz="-0.025571 0.370084 -0.330926" rpy="0 0 0"/>
    <geometry>
      <mesh filename="file://$(find zine_rover_description)/meshes/right_leg_link_1.stl" scale="0.001 0.001 0.001"/>
    </geometry>
  </collision>
</link>

<link name="r3_link_1">
  <inertial>
    <origin xyz="-0.00017925524376938284 0.03075863249014632 -0.0006166366501741266" rpy="0 0 0"/>
    <mass value="7.008299929640141"/>
    <inertia ixx="0.028649" iyy="0.052079" izz="0.028789" ixy="1e-06" iyz="2e-06" ixz="-5e-06"/>
  </inertial>
  <visual>
    <origin xyz="0.357593 0.396347 -0.110404" rpy="0 0 0"/>
    <geometry>
      <mesh filename="file://$(find zine_rover_description)/meshes/r3_link_1.stl" scale="0.001 0.001 0.001"/>
    </geometry>
    <material name="silver"/>
  </visual>
  <collision>
    <origin xyz="0.357593 0.396347 -0.110404" rpy="0 0 0"/>
    <geometry>
      <mesh filename="file://$(find zine_rover_description)/meshes/r3_link_1.stl" scale="0.001 0.001 0.001"/>
    </geometry>
  </collision>
</link>

<link name="r2_link_1">
  <inertial>
    <origin xyz="-0.00019068765485445727 0.03075863249055144 -0.0006126517346900229" rpy="0 0 0"/>
    <mass value="7.008299929640126"/>
    <inertia ixx="0.028649" iyy="0.052079" izz="0.028789" ixy="1e-06" iyz="2e-06" ixz="-3e-06"/>
  </inertial>
  <visual>
    <origin xyz="-0.026925 0.394047 -0.114116" rpy="0 0 0"/>
    <geometry>
      <mesh filename="file://$(find zine_rover_description)/meshes/r2_link_1.stl" scale="0.001 0.001 0.001"/>
    </geometry>
    <material name="silver"/>
  </visual>
  <collision>
    <origin xyz="-0.026925 0.394047 -0.114116" rpy="0 0 0"/>
    <geometry>
      <mesh filename="file://$(find zine_rover_description)/meshes/r2_link_1.stl" scale="0.001 0.001 0.001"/>
    </geometry>
  </collision>
</link>

<link name="r1_link_1">
  <inertial>
    <origin xyz="0.00021185036765086762 0.030758632490848592 0.0006053496806429359" rpy="0 0 0"/>
    <mass value="7.008299929640157"/>
    <inertia ixx="0.028649" iyy="0.052079" izz="0.028789" ixy="-1e-06" iyz="-2e-06" ixz="2e-06"/>
  </inertial>
  <visual>
    <origin xyz="-0.410467 0.395997 -0.112676" rpy="0 0 0"/>
    <geometry>
      <mesh filename="file://$(find zine_rover_description)/meshes/r1_link_1.stl" scale="0.001 0.001 0.001"/>
    </geometry>
    <material name="silver"/>
  </visual>
  <collision>
    <origin xyz="-0.410467 0.395997 -0.112676" rpy="0 0 0"/>
    <geometry>
      <mesh filename="file://$(find zine_rover_description)/meshes/r1_link_1.stl" scale="0.001 0.001 0.001"/>
    </geometry>
  </collision>
</link>

<link name="l3_link_1">
  <inertial>
    <origin xyz="-0.00017925524364587053 -0.030758732308784564 -0.0006166366501741682" rpy="0 0 0"/>
    <mass value="7.008299929640113"/>
    <inertia ixx="0.028649" iyy="0.052079" izz="0.028789" ixy="-1e-06" iyz="-2e-06" ixz="-5e-06"/>
  </inertial>
  <visual>
    <origin xyz="0.357593 -0.400459 -0.110404" rpy="0 0 0"/>
    <geometry>
      <mesh filename="file://$(find zine_rover_description)/meshes/l3_link_1.stl" scale="0.001 0.001 0.001"/>
    </geometry>
    <material name="silver"/>
  </visual>
  <collision>
    <origin xyz="0.357593 -0.400459 -0.110404" rpy="0 0 0"/>
    <geometry>
      <mesh filename="file://$(find zine_rover_description)/meshes/l3_link_1.stl" scale="0.001 0.001 0.001"/>
    </geometry>
  </collision>
</link>

<link name="l2_link_1">
  <inertial>
    <origin xyz="0.00018998984029418992 -0.030758732309175196 0.0006132686592397046" rpy="0 0 0"/>
    <mass value="7.008299929640119"/>
    <inertia ixx="0.028649" iyy="0.052079" izz="0.028789" ixy="1e-06" iyz="2e-06" ixz="-3e-06"/>
  </inertial>
  <visual>
    <origin xyz="-0.026925 -0.398159 -0.114116" rpy="0 0 0"/>
    <geometry>
      <mesh filename="file://$(find zine_rover_description)/meshes/l2_link_1.stl" scale="0.001 0.001 0.001"/>
    </geometry>
    <material name="silver"/>
  </visual>
  <collision>
    <origin xyz="-0.026925 -0.398159 -0.114116" rpy="0 0 0"/>
    <geometry>
      <mesh filename="file://$(find zine_rover_description)/meshes/l2_link_1.stl" scale="0.001 0.001 0.001"/>
    </geometry>
  </collision>
</link>

<link name="l1_link_1">
  <inertial>
    <origin xyz="0.00021185036776399935 -0.030758732309567827 0.0006053496806437547" rpy="0 0 0"/>
    <mass value="7.008299929640155"/>
    <inertia ixx="0.028649" iyy="0.052079" izz="0.028789" ixy="1e-06" iyz="2e-06" ixz="2e-06"/>
  </inertial>
  <visual>
    <origin xyz="-0.410467 -0.400109 -0.112676" rpy="0 0 0"/>
    <geometry>
      <mesh filename="file://$(find zine_rover_description)/meshes/l1_link_1.stl" scale="0.001 0.001 0.001"/>
    </geometry>
    <material name="silver"/>
  </visual>
  <collision>
    <origin xyz="-0.410467 -0.400109 -0.112676" rpy="0 0 0"/>
    <geometry>
      <mesh filename="file://$(find zine_rover_description)/meshes/l1_link_1.stl" scale="0.001 0.001 0.001"/>
    </geometry>
  </collision>
</link>

<link name="left_leg_link_1">
  <inertial>
    <origin xyz="-0.0013207471590895165 -0.06659229508359005 -0.10929147983765616" rpy="0 0 0"/>
    <mass value="16.471253218381243"/>
    <inertia ixx="0.117612" iyy="0.774902" izz="0.677974" ixy="0.000289" iyz="0.008207" ixz="-0.000244"/>
  </inertial>
  <visual>
    <origin xyz="-0.025571 -0.374196 -0.330926" rpy="0 0 0"/>
    <geometry>
      <mesh filename="file://$(find zine_rover_description)/meshes/left_leg_link_1.stl" scale="0.001 0.001 0.001"/>
    </geometry>
    <material name="silver"/>
  </visual>
  <collision>
    <origin xyz="-0.025571 -0.374196 -0.330926" rpy="0 0 0"/>
    <geometry>
      <mesh filename="file://$(find zine_rover_description)/meshes/left_leg_link_1.stl" scale="0.001 0.001 0.001"/>
    </geometry>
  </collision>
</link>


<link name="laser_link_1">
  <inertial>
    <origin xyz="-1.0925525761873445e-10 1.7081667261754058e-12 0.019999500000943637" rpy="0 0 0"/>
    <mass value="3.3146897084726623"/>
    <inertia ixx="0.003392" iyy="0.003392" izz="0.0059" ixy="-0.0" iyz="0.0" ixz="-0.0"/>
  </inertial>
  <visual>
    <origin xyz="-0.123 -0.0 -0.429375" rpy="0 0 0"/>
    <geometry>
      <mesh filename="file://$(find zine_rover_description)/meshes/laser_link_1.stl" scale="0.001 0.001 0.001"/>
    </geometry>
    <material name="silver"/>
  </visual>
  <collision>
    <origin xyz="-0.123 -0.0 -0.429375" rpy="0 0 0"/>
    <geometry>
      <mesh filename="file://$(find zine_rover_description)/meshes/laser_link_1.stl" scale="0.001 0.001 0.001"/>
    </geometry>
  </collision>
</link>


<link name="camera_bottom_screw_frame">
  <inertial>
    <origin xyz="0.012500040998467493 1.7078279068716285e-12 1.2811418592661994e-12" rpy="0 0 0"/>
    <inertia ixx="0.001" iyy="0.001" izz="0.001" ixy="0.000" iyz="0.000" ixz="0.000"/>
    <mass value="0.564"/>
  </inertial>
  <visual>
    <origin xyz="-0.166 -0.0 -0.2" rpy="0 0 0"/>
    <geometry>
      <mesh filename="file://$(find zine_rover_description)/meshes/camera_link_1.stl" scale="0.001 0.001 0.001"/>
    </geometry>
    <material name="silver"/>
  </visual>
  <collision>
    <origin xyz="-0.166 -0.0 -0.2" rpy="0 0 0"/>
    <geometry>
      <mesh filename="file://$(find zine_rover_description)/meshes/camera_link_1.stl" scale="0.001 0.001 0.001"/>
    </geometry>
    <material name="silver"/>
  </collision>
</link>

<link name="camera_link"></link>

<link name="camera_depth_frame"></link>

<link name="camera_depth_optical_frame"></link>

<link name="camera_color_frame"></link>

<link name="camera_color_optical_frame"></link>

<link name="camera_left_ir_frame"></link>

<link name="camera_left_ir_optical_frame"></link>

<link name="camera_right_ir_frame"></link>

<link name="camera_right_ir_optical_frame"></link>


<link name="base_footprint">
  <box_inertia m="0" w="0" d="0" h="0"/>
</link>

<joint name="base_joint" type="fixed">
  <parent link="base_link"/>
  <child link="base_footprint"/>
  <origin xyz="0 0 0" rpy="0 0 0"/>
</joint>

<joint name="right_leg_joint" type="fixed">
  <origin xyz="0.025571 -0.370084 0.330926" rpy="0 0 0"/>
  <parent link="base_link"/>
  <child link="right_leg_link_1"/>
</joint>

<joint name="r3_joint" type="continuous">
  <origin xyz="-0.383164 -0.026263 -0.220522" rpy="0 0 ${-pi}"/>
  <parent link="right_leg_link_1"/>
  <child link="r3_link_1"/>
  <axis xyz="0.0 -1.0 0.0"/>
</joint>

<joint name="r2_joint" type="continuous">
  <origin xyz="0.001354 -0.023963 -0.21681" rpy="0 0 ${-pi}"/>
  <parent link="right_leg_link_1"/>
  <child link="r2_link_1"/>
  <axis xyz="0.0 -1.0 0.0"/>
</joint>

<joint name="r1_joint" type="continuous">
  <origin xyz="0.384896 -0.025913 -0.21825" rpy="0 0 ${-pi}"/>net
  <parent link="right_leg_link_1"/>
  <child link="r1_link_1"/>
  <axis xyz="0.0 -1.0 0.0"/>
</joint>

<joint name="l3_joint" type="continuous">
  <origin xyz="-0.383164 0.026263 -0.220522" rpy="0 0 0"/>
  <parent link="left_leg_link_1"/>
  <child link="l3_link_1"/>
  <axis xyz="-0.0 1.0 -0.0"/>
</joint>

<joint name="l2_joint" type="continuous">
  <origin xyz="0.001354 0.023963 -0.21681" rpy="0 0 0"/>
  <parent link="left_leg_link_1"/>
  <child link="l2_link_1"/>
  <axis xyz="0.0 1.0 0.0"/>
</joint>

<joint name="l1_jont" type="continuous">
  <origin xyz="0.384896 0.025913 -0.21825" rpy="0 0 0"/>
  <parent link="left_leg_link_1"/>
  <child link="l1_link_1"/>
  <axis xyz="-0.0 1.0 -0.0"/>
</joint>

<joint name="left_leg_joint" type="fixed">
  <origin xyz="0.025571 0.374196 0.330926" rpy="0 0 0"/>
  <parent link="base_link"/>
  <child link="left_leg_link_1"/>
</joint>



<joint name="laser_joint" type="fixed">
  <origin xyz="0.123 0.0 0.429375" rpy="0 0 0"/>
  <parent link="base_link"/>
  <child link="laser_link_1"/>
  <axis xyz="-0.0 0.0 1.0"/>
</joint>

<joint name="camera_joint" type="fixed">
  <parent link="base_link" />
  <child link="camera_bottom_screw_frame" />
  <origin xyz="0.166 0.0 0.2" rpy="0 0 0"/>
</joint>

<joint name="camera_link_joint" type="fixed">
  <parent link="camera_bottom_screw_frame" />
  <child link="camera_link" />
  <origin xyz="0.045 0.016 0.0125 " rpy="0 0 0" />
</joint>

<joint name="camera_depth_joint" type="fixed">
  <parent link="camera_link" />
  <child link="camera_depth_frame" />
  <origin xyz="0 0 0" rpy="0 0 0" />
</joint>

<joint name="camera_depth_optical_joint" type="fixed">
  <parent link="camera_depth_frame" />
  <child link="camera_depth_optical_frame" />
  <origin xyz="0 0 0 " rpy="-1.57 0 -1.57" />
</joint>

<joint name="camera_color_joint" type="fixed">
  <parent link="camera_depth_frame" />
  <child link="camera_color_frame" />
  <origin xyz="0 0 0" rpy="0 0 0" />
</joint>

<joint name="camera_color_optical_joint" type="fixed">
  <parent link="camera_color_frame" />
  <child link="camera_color_optical_frame" />
  <origin xyz="0 0 0 " rpy="-1.57 0 -1.57" />
</joint>

<joint name="camera_left_ir_joint" type="fixed">
  <parent link="camera_depth_frame" />
  <child link="camera_left_ir_frame" />
  <origin xyz="0 0 0 " rpy="0 0 0 " />
</joint>

<joint name="camera_left_ir_optical_joint" type="fixed">
  <parent link="camera_left_ir_frame" />
  <child link="camera_left_ir_optical_frame" />
  <origin xyz="0 0 0 " rpy="-1.57 0 -1.57" />
</joint>

<joint name="camera_right_ir_joint" type="fixed">
  <parent link="camera_depth_frame" />
  <child link="camera_right_ir_frame" />
  <origin xyz="0 -0.050 0 " rpy="0 0 0" />
</joint>

<joint name="camera_right_ir_optical_joint" type="fixed">
  <parent link="camera_right_ir_frame" />
  <child link="camera_right_ir_optical_frame" />
  <origin xyz="0 0 0 " rpy="-1.57 0 -1.57" />
</joint>


</robot>
