<?xml version="1.0" ?>
<robot name="isroarm" xmlns:xacro="http://www.ros.org/wiki/xacro">

<xacro:include filename="$(find isroarm_description)/urdf/materials.xacro" />
<xacro:include filename="$(find isroarm_description)/urdf/isroarm.trans" />
<xacro:include filename="$(find isroarm_description)/urdf/isroarm.gazebo" />
<link name="base_link">
  <inertial>
    <origin xyz="-0.006223035523270263 0.0002504182034910796 0.08547439505557328" rpy="0 0 0"/>
    <mass value="34.39674031575615"/>
    <inertia ixx="0.846383" iyy="0.8519" izz="1.40519" ixy="0.000683" iyz="-9.6e-05" ixz="-0.013757"/>
  </inertial>
  <visual>
    <origin xyz="0 0 0" rpy="0 0 0"/>
    <geometry>
      <mesh filename="file://$(find isroarm_description)/meshes/base_link.stl" scale="0.001 0.001 0.001"/>
    </geometry>
    <material name="silver"/>
  </visual>
  <collision>
    <origin xyz="0 0 0" rpy="0 0 0"/>
    <geometry>
      <mesh filename="file://$(find isroarm_description)/meshes/base_link.stl" scale="0.001 0.001 0.001"/>
    </geometry>
  </collision>
</link>

<link name="limb2_1">
  <inertial>
    <origin xyz="-0.0010583101465876932 0.027332460893030076 0.24659669730045924" rpy="0 0 0"/>
    <mass value="9.727222371945627"/>
    <inertia ixx="0.475806" iyy="0.397211" izz="0.080891" ixy="-3e-06" iyz="0.002402" ixz="-8e-06"/>
  </inertial>
  <visual>
    <origin xyz="-0.120545 0.025652 -0.319189" rpy="0 0 0"/>
    <geometry>
      <mesh filename="file://$(find isroarm_description)/meshes/limb2_1.stl" scale="0.001 0.001 0.001"/>
    </geometry>
    <material name="silver"/>
  </visual>
  <collision>
    <origin xyz="-0.120545 0.025652 -0.319189" rpy="0 0 0"/>
    <geometry>
      <mesh filename="file://$(find isroarm_description)/meshes/limb2_1.stl" scale="0.001 0.001 0.001"/>
    </geometry>
  </collision>
</link>

<link name="limb3_1">
  <inertial>
    <origin xyz="0.09312517589687319 0.05857578303732136 0.0036645101411612035" rpy="0 0 0"/>
    <mass value="6.4774993512068155"/>
    <inertia ixx="0.011715" iyy="0.090775" izz="0.087272" ixy="-5.6e-05" iyz="-4.6e-05" ixz="0.000519"/>
  </inertial>
  <visual>
    <origin xyz="-0.119445 0.056552 -0.833533" rpy="0 0 0"/>
    <geometry>
      <mesh filename="file://$(find isroarm_description)/meshes/limb3_1.stl" scale="0.001 0.001 0.001"/>
    </geometry>
    <material name="silver"/>
  </visual>
  <collision>
    <origin xyz="-0.119445 0.056552 -0.833533" rpy="0 0 0"/>
    <geometry>
      <mesh filename="file://$(find isroarm_description)/meshes/limb3_1.stl" scale="0.001 0.001 0.001"/>
    </geometry>
  </collision>
</link>

<link name="limb4_1">
  <inertial>
    <origin xyz="-0.030623225094261186 0.01328740661062281 0.003764742683460165" rpy="0 0 0"/>
    <mass value="1.462466051492862"/>
    <inertia ixx="0.003369" iyy="0.001" izz="0.003487" ixy="-0.000232" iyz="4e-05" ixz="6.6e-05"/>
  </inertial>
  <visual>
    <origin xyz="-0.599877 -0.007098 -0.835025" rpy="0 0 0"/>
    <geometry>
      <mesh filename="file://$(find isroarm_description)/meshes/limb4_1.stl" scale="0.001 0.001 0.001"/>
    </geometry>
    <material name="silver"/>
  </visual>
  <collision>
    <origin xyz="-0.599877 -0.007098 -0.835025" rpy="0 0 0"/>
    <geometry>
      <mesh filename="file://$(find isroarm_description)/meshes/limb4_1.stl" scale="0.001 0.001 0.001"/>
    </geometry>
  </collision>
</link>

<link name="limb5_1">
  <inertial>
    <origin xyz="0.09993112071423671 0.029429865518363095 0.00037554982914056456" rpy="0 0 0"/>
    <mass value="0.2954171108490884"/>
    <inertia ixx="0.000547" iyy="0.001224" izz="0.001484" ixy="-0.000139" iyz="9e-06" ixz="-3.4e-05"/>
  </inertial>
  <visual>
    <origin xyz="-0.59765 -0.00911 -0.83644" rpy="0 0 0"/>
    <geometry>
      <mesh filename="file://$(find isroarm_description)/meshes/limb5_1.stl" scale="0.001 0.001 0.001"/>
    </geometry>
    <material name="silver"/>
  </visual>
  <collision>
    <origin xyz="-0.59765 -0.00911 -0.83644" rpy="0 0 0"/>
    <geometry>
      <mesh filename="file://$(find isroarm_description)/meshes/limb5_1.stl" scale="0.001 0.001 0.001"/>
    </geometry>
  </collision>
</link>

<link name="limb6_1">
  <inertial>
    <origin xyz="0.04909576354112366 0.0339011096498328 0.000673574815664213" rpy="0 0 0"/>
    <mass value="1.1785854860286602"/>
    <inertia ixx="0.0008" iyy="0.002757" izz="0.002011" ixy="-7.7e-05" iyz="7e-06" ixz="-1.3e-05"/>
  </inertial>
  <visual>
    <origin xyz="-0.69365 0.037515 -0.837685" rpy="0 0 0"/>
    <geometry>
      <mesh filename="file://$(find isroarm_description)/meshes/limb6_1.stl" scale="0.001 0.001 0.001"/>
    </geometry>
    <material name="silver"/>
  </visual>
  <collision>
    <origin xyz="-0.69365 0.037515 -0.837685" rpy="0 0 0"/>
    <geometry>
      <mesh filename="file://$(find isroarm_description)/meshes/limb6_1.stl" scale="0.001 0.001 0.001"/>
    </geometry>
  </collision>
</link>

<link name="limb1_1">
  <inertial>
    <origin xyz="-0.01638798223083897 -0.0008646361197985808 0.028718199102967357" rpy="0 0 0"/>
    <mass value="16.43447240161675"/>
    <inertia ixx="0.161532" iyy="0.058708" izz="0.190372" ixy="6.8e-05" iyz="-0.000181" ixz="-0.004139"/>
  </inertial>
  <visual>
    <origin xyz="-0.122962 -0.000501 -0.229333" rpy="0 0 0"/>
    <geometry>
      <mesh filename="file://$(find isroarm_description)/meshes/limb1_1.stl" scale="0.001 0.001 0.001"/>
    </geometry>
    <material name="silver"/>
  </visual>
  <collision>
    <origin xyz="-0.122962 -0.000501 -0.229333" rpy="0 0 0"/>
    <geometry>
      <mesh filename="file://$(find isroarm_description)/meshes/limb1_1.stl" scale="0.001 0.001 0.001"/>
    </geometry>
  </collision>
</link>

<joint name="Revolute 13" type="continuous">
  <origin xyz="-0.002417 -0.026153 0.089856" rpy="0 0 0"/>
  <parent link="limb1_1"/>
  <child link="limb2_1"/>
  <axis xyz="-0.0 1.0 0.0"/>
</joint>

<joint name="Revolute 14" type="continuous">
  <origin xyz="-0.0011 -0.0309 0.514344" rpy="0 0 0"/>
  <parent link="limb2_1"/>
  <child link="limb3_1"/>
  <axis xyz="0.0 -1.0 0.0"/>
</joint>

<joint name="Revolute 15" type="continuous">
  <origin xyz="0.480432 0.06365 0.001492" rpy="0 0 0"/>
  <parent link="limb3_1"/>
  <child link="limb4_1"/>
  <axis xyz="0.999949 0.0 0.010127"/>
</joint>

<joint name="Revolute 16" type="continuous">
  <origin xyz="-0.002227 0.002012 0.001415" rpy="0 0 0"/>
  <parent link="limb4_1"/>
  <child link="limb5_1"/>
  <axis xyz="-0.000103 0.999949 0.010126"/>
</joint>

<joint name="Slider 17" type="prismatic">
  <origin xyz="0.096 -0.046625 0.001245" rpy="0 0 0"/>
  <parent link="limb5_1"/>
  <child link="limb6_1"/>
  <axis xyz="0.000103 -0.999949 -0.010126"/>
  <limit upper="0.08" lower="0.0" effort="100" velocity="100"/>
</joint>

<joint name="Revolute 19" type="continuous">
  <origin xyz="0.122962 0.000501 0.229333" rpy="0 0 0"/>
  <parent link="base_link"/>
  <child link="limb1_1"/>
  <axis xyz="-0.0 0.0 1.0"/>
</joint>

</robot>
